2025-09-19 01:07:54,752 INFO    MainThread:3554344 [wandb_setup.py:_flush():81] Current SDK version is 0.21.4
2025-09-19 01:07:54,752 INFO    MainThread:3554344 [wandb_setup.py:_flush():81] Configure stats pid to 3554344
2025-09-19 01:07:54,752 INFO    MainThread:3554344 [wandb_setup.py:_flush():81] Loading settings from /home/aiotlab/.config/wandb/settings
2025-09-19 01:07:54,752 INFO    MainThread:3554344 [wandb_setup.py:_flush():81] Loading settings from /mnt/disk1/aiotlab/namth/EEGFoundationModel/EEGPT/wandb/settings
2025-09-19 01:07:54,752 INFO    MainThread:3554344 [wandb_setup.py:_flush():81] Loading settings from environment variables
2025-09-19 01:07:54,752 INFO    MainThread:3554344 [wandb_init.py:setup_run_log_directory():686] Logging user logs to /mnt/disk1/aiotlab/namth/EEGFoundationModel/EEGPT/wandb/run-20250919_010754-onwu5q5s/logs/debug.log
2025-09-19 01:07:54,752 INFO    MainThread:3554344 [wandb_init.py:setup_run_log_directory():687] Logging internal logs to /mnt/disk1/aiotlab/namth/EEGFoundationModel/EEGPT/wandb/run-20250919_010754-onwu5q5s/logs/debug-internal.log
2025-09-19 01:07:54,753 INFO    MainThread:3554344 [wandb_init.py:init():813] calling init triggers
2025-09-19 01:07:54,753 INFO    MainThread:3554344 [wandb_init.py:init():818] wandb.init called with sweep_config: {}
config: {'project_name': 'EEGFoundationModel', 'modality_mode': 'mono', 'num_folds': -1, 'seed': 3407, 'cuda': 0, 'epochs': 50, 'batch_size': 8, 'lr': 0.0001, 'weight_decay': 0.05, 'optimizer': 'AdamW', 'clip_value': 1, 'dropout': 0.1, 'downstream_dataset': 'PEARL', 'datasets_dir': '/mnt/disk1/aiotlab/namth/EEGFoundationModel/datasets/pearl_30s_oldnumpy', 'num_of_classes': 2, 'model_dir': './data/wjq/models_weights/Big/BigFaced', 'num_workers': 16, 'label_smoothing': 0.1, 'multi_lr': False, 'frozen': False, 'use_pretrained_weights': True, 'foundation_dir': '/mnt/disk1/aiotlab/namth/EEGFoundationModel/EEGPT/checkpoint/eegpt_mcae_58chs_4s_large4E.ckpt', '_wandb': {}}
2025-09-19 01:07:54,753 INFO    MainThread:3554344 [wandb_init.py:init():854] starting backend
2025-09-19 01:07:54,961 INFO    MainThread:3554344 [wandb_init.py:init():857] sending inform_init request
2025-09-19 01:07:54,966 INFO    MainThread:3554344 [wandb_init.py:init():865] backend started and connected
2025-09-19 01:07:54,968 INFO    MainThread:3554344 [wandb_init.py:init():936] updated telemetry
2025-09-19 01:07:54,973 INFO    MainThread:3554344 [wandb_init.py:init():960] communicating run to backend with 90.0 second timeout
2025-09-19 01:07:56,434 INFO    MainThread:3554344 [wandb_init.py:init():1011] starting run threads in backend
2025-09-19 01:07:56,697 INFO    MainThread:3554344 [wandb_run.py:_console_start():2506] atexit reg
2025-09-19 01:07:56,697 INFO    MainThread:3554344 [wandb_run.py:_redirect():2354] redirect: wrap_raw
2025-09-19 01:07:56,697 INFO    MainThread:3554344 [wandb_run.py:_redirect():2423] Wrapping output streams.
2025-09-19 01:07:56,697 INFO    MainThread:3554344 [wandb_run.py:_redirect():2446] Redirects installed.
2025-09-19 01:07:56,699 INFO    MainThread:3554344 [wandb_init.py:init():1049] run started, returning control to user process
2025-09-19 01:11:47,824 INFO    wandb-AsyncioManager-main:3554344 [service_client.py:_forward_responses():84] Reached EOF.
2025-09-19 01:11:47,825 INFO    wandb-AsyncioManager-main:3554344 [mailbox.py:close():137] Closing mailbox, abandoning 1 handles.
2025-09-19 01:11:48,766 ERROR   wandb-AsyncioManager-main:3554344 [asyncio_manager.py:fn_wrap_exceptions():183] Uncaught exception in run_soon callback.
Traceback (most recent call last):
  File "/mnt/disk1/aiotlab/envs/hoainiemeegpt/lib/python3.11/site-packages/wandb/sdk/lib/asyncio_manager.py", line 181, in fn_wrap_exceptions
    await fn()
  File "/mnt/disk1/aiotlab/envs/hoainiemeegpt/lib/python3.11/site-packages/wandb/sdk/lib/service/service_client.py", line 65, in _send_server_request
    await self._writer.drain()
  File "/mnt/disk1/aiotlab/envs/hoainiemeegpt/lib/python3.11/asyncio/streams.py", line 392, in drain
    await self._protocol._drain_helper()
  File "/mnt/disk1/aiotlab/envs/hoainiemeegpt/lib/python3.11/asyncio/streams.py", line 166, in _drain_helper
    raise ConnectionResetError('Connection lost')
ConnectionResetError: Connection lost
2025-09-19 01:11:48,773 ERROR   wandb-AsyncioManager-main:3554344 [asyncio_manager.py:fn_wrap_exceptions():183] Uncaught exception in run_soon callback.
Traceback (most recent call last):
  File "/mnt/disk1/aiotlab/envs/hoainiemeegpt/lib/python3.11/site-packages/wandb/sdk/lib/asyncio_manager.py", line 181, in fn_wrap_exceptions
    await fn()
  File "/mnt/disk1/aiotlab/envs/hoainiemeegpt/lib/python3.11/site-packages/wandb/sdk/lib/service/service_client.py", line 65, in _send_server_request
    await self._writer.drain()
  File "/mnt/disk1/aiotlab/envs/hoainiemeegpt/lib/python3.11/asyncio/streams.py", line 392, in drain
    await self._protocol._drain_helper()
  File "/mnt/disk1/aiotlab/envs/hoainiemeegpt/lib/python3.11/asyncio/streams.py", line 166, in _drain_helper
    raise ConnectionResetError('Connection lost')
ConnectionResetError: Connection lost
2025-09-19 01:11:48,775 ERROR   wandb-AsyncioManager-main:3554344 [asyncio_manager.py:fn_wrap_exceptions():183] Uncaught exception in run_soon callback.
Traceback (most recent call last):
  File "/mnt/disk1/aiotlab/envs/hoainiemeegpt/lib/python3.11/site-packages/wandb/sdk/lib/asyncio_manager.py", line 181, in fn_wrap_exceptions
    await fn()
  File "/mnt/disk1/aiotlab/envs/hoainiemeegpt/lib/python3.11/site-packages/wandb/sdk/lib/service/service_client.py", line 65, in _send_server_request
    await self._writer.drain()
  File "/mnt/disk1/aiotlab/envs/hoainiemeegpt/lib/python3.11/asyncio/streams.py", line 392, in drain
    await self._protocol._drain_helper()
  File "/mnt/disk1/aiotlab/envs/hoainiemeegpt/lib/python3.11/asyncio/streams.py", line 166, in _drain_helper
    raise ConnectionResetError('Connection lost')
ConnectionResetError: Connection lost
2025-09-19 01:11:48,797 ERROR   wandb-AsyncioManager-main:3554344 [asyncio_manager.py:fn_wrap_exceptions():183] Uncaught exception in run_soon callback.
Traceback (most recent call last):
  File "/mnt/disk1/aiotlab/envs/hoainiemeegpt/lib/python3.11/site-packages/wandb/sdk/lib/asyncio_manager.py", line 181, in fn_wrap_exceptions
    await fn()
  File "/mnt/disk1/aiotlab/envs/hoainiemeegpt/lib/python3.11/site-packages/wandb/sdk/lib/service/service_client.py", line 65, in _send_server_request
    await self._writer.drain()
  File "/mnt/disk1/aiotlab/envs/hoainiemeegpt/lib/python3.11/asyncio/streams.py", line 392, in drain
    await self._protocol._drain_helper()
  File "/mnt/disk1/aiotlab/envs/hoainiemeegpt/lib/python3.11/asyncio/streams.py", line 166, in _drain_helper
    raise ConnectionResetError('Connection lost')
ConnectionResetError: Connection lost
