2025-09-22 20:26:54,445 INFO    MainThread:1642646 [wandb_init.py:setup_run_log_directory():686] Logging user logs to /mnt/disk1/aiotlab/namth/EEGFoundationModel/EEGPT/wandb/run-20250922_202654-zizwrfji/logs/debug.log
2025-09-22 20:26:54,445 INFO    MainThread:1642646 [wandb_init.py:setup_run_log_directory():687] Logging internal logs to /mnt/disk1/aiotlab/namth/EEGFoundationModel/EEGPT/wandb/run-20250922_202654-zizwrfji/logs/debug-internal.log
2025-09-22 20:26:54,445 INFO    MainThread:1642646 [wandb_init.py:init():813] calling init triggers
2025-09-22 20:26:54,445 INFO    MainThread:1642646 [wandb_init.py:init():818] wandb.init called with sweep_config: {}
config: {'project_name': 'EEGPT-pearl', 'modality_mode': 'multi', 'num_folds': -1, 'seed': 3407, 'cuda': 0, 'epochs': 100, 'batch_size': 32, 'lr': 0.0003, 'weight_decay': 0.05, 'optimizer': 'AdamW', 'clip_value': 1, 'dropout': 0.1, 'downstream_dataset': 'PEARL', 'datasets_dir': '/mnt/disk1/aiotlab/namth/EEGFoundationModel/datasets/pearl_30s_oldnumpy/108/fold_0', 'num_of_classes': 2, 'model_dir': './data/wjq/models_weights/Big/BigFaced', 'num_workers': 16, 'label_smoothing': 0.1, 'multi_lr': False, 'frozen': True, 'use_pretrained_weights': True, 'foundation_dir': '/mnt/disk1/aiotlab/namth/EEGFoundationModel/EEGPT/checkpoint/108.ckpt', 'patch_size': 200, 'img_size': [19, 6000], '_wandb': {}}
2025-09-22 20:26:54,445 INFO    MainThread:1642646 [wandb_init.py:init():854] starting backend
2025-09-22 20:26:54,445 INFO    MainThread:1642646 [wandb_init.py:init():857] sending inform_init request
2025-09-22 20:26:54,449 INFO    MainThread:1642646 [wandb_init.py:init():865] backend started and connected
2025-09-22 20:26:54,467 INFO    MainThread:1642646 [wandb_init.py:init():936] updated telemetry
2025-09-22 20:26:54,478 INFO    MainThread:1642646 [wandb_init.py:init():960] communicating run to backend with 90.0 second timeout
2025-09-22 20:26:55,412 INFO    MainThread:1642646 [wandb_init.py:init():1011] starting run threads in backend
2025-09-22 20:26:55,719 INFO    MainThread:1642646 [wandb_run.py:_console_start():2506] atexit reg
2025-09-22 20:26:55,719 INFO    MainThread:1642646 [wandb_run.py:_redirect():2354] redirect: wrap_raw
2025-09-22 20:26:55,719 INFO    MainThread:1642646 [wandb_run.py:_redirect():2423] Wrapping output streams.
2025-09-22 20:26:55,719 INFO    MainThread:1642646 [wandb_run.py:_redirect():2446] Redirects installed.
2025-09-22 20:26:55,720 INFO    MainThread:1642646 [wandb_init.py:init():1049] run started, returning control to user process
2025-09-22 20:26:58,252 ERROR   wandb-AsyncioManager-main:1642646 [asyncio_manager.py:fn_wrap_exceptions():183] Uncaught exception in run_soon callback.
Traceback (most recent call last):
  File "/mnt/disk1/aiotlab/envs/hoainiemeegpt/lib/python3.11/site-packages/wandb/sdk/lib/asyncio_manager.py", line 181, in fn_wrap_exceptions
    await fn()
  File "/mnt/disk1/aiotlab/envs/hoainiemeegpt/lib/python3.11/site-packages/wandb/sdk/lib/service/service_client.py", line 65, in _send_server_request
    await self._writer.drain()
  File "/mnt/disk1/aiotlab/envs/hoainiemeegpt/lib/python3.11/asyncio/streams.py", line 392, in drain
    await self._protocol._drain_helper()
  File "/mnt/disk1/aiotlab/envs/hoainiemeegpt/lib/python3.11/asyncio/streams.py", line 166, in _drain_helper
    raise ConnectionResetError('Connection lost')
ConnectionResetError: Connection lost
2025-09-22 20:26:58,300 ERROR   wandb-AsyncioManager-main:1642646 [asyncio_manager.py:fn_wrap_exceptions():183] Uncaught exception in run_soon callback.
Traceback (most recent call last):
  File "/mnt/disk1/aiotlab/envs/hoainiemeegpt/lib/python3.11/site-packages/wandb/sdk/lib/asyncio_manager.py", line 181, in fn_wrap_exceptions
    await fn()
  File "/mnt/disk1/aiotlab/envs/hoainiemeegpt/lib/python3.11/site-packages/wandb/sdk/lib/service/service_client.py", line 65, in _send_server_request
    await self._writer.drain()
  File "/mnt/disk1/aiotlab/envs/hoainiemeegpt/lib/python3.11/asyncio/streams.py", line 392, in drain
    await self._protocol._drain_helper()
  File "/mnt/disk1/aiotlab/envs/hoainiemeegpt/lib/python3.11/asyncio/streams.py", line 166, in _drain_helper
    raise ConnectionResetError('Connection lost')
ConnectionResetError: Connection lost
2025-09-22 20:26:58,302 ERROR   wandb-AsyncioManager-main:1642646 [asyncio_manager.py:fn_wrap_exceptions():183] Uncaught exception in run_soon callback.
Traceback (most recent call last):
  File "/mnt/disk1/aiotlab/envs/hoainiemeegpt/lib/python3.11/site-packages/wandb/sdk/lib/asyncio_manager.py", line 181, in fn_wrap_exceptions
    await fn()
  File "/mnt/disk1/aiotlab/envs/hoainiemeegpt/lib/python3.11/site-packages/wandb/sdk/lib/service/service_client.py", line 65, in _send_server_request
    await self._writer.drain()
  File "/mnt/disk1/aiotlab/envs/hoainiemeegpt/lib/python3.11/asyncio/streams.py", line 392, in drain
    await self._protocol._drain_helper()
  File "/mnt/disk1/aiotlab/envs/hoainiemeegpt/lib/python3.11/asyncio/streams.py", line 166, in _drain_helper
    raise ConnectionResetError('Connection lost')
ConnectionResetError: Connection lost
2025-09-22 20:26:58,329 ERROR   wandb-AsyncioManager-main:1642646 [asyncio_manager.py:fn_wrap_exceptions():183] Uncaught exception in run_soon callback.
Traceback (most recent call last):
  File "/mnt/disk1/aiotlab/envs/hoainiemeegpt/lib/python3.11/site-packages/wandb/sdk/lib/asyncio_manager.py", line 181, in fn_wrap_exceptions
    await fn()
  File "/mnt/disk1/aiotlab/envs/hoainiemeegpt/lib/python3.11/site-packages/wandb/sdk/lib/service/service_client.py", line 65, in _send_server_request
    await self._writer.drain()
  File "/mnt/disk1/aiotlab/envs/hoainiemeegpt/lib/python3.11/asyncio/streams.py", line 392, in drain
    await self._protocol._drain_helper()
  File "/mnt/disk1/aiotlab/envs/hoainiemeegpt/lib/python3.11/asyncio/streams.py", line 166, in _drain_helper
    raise ConnectionResetError('Connection lost')
ConnectionResetError: Connection lost
